KeyError: 'source_name'
Traceback:
File "/home/runner/workspace/.pythonlibs/lib/python3.11/site-packages/streamlit/runtime/scriptrunner/exec_code.py", line 88, in exec_func_with_error_handling
    result = func()
             ^^^^^^
File "/home/runner/workspace/.pythonlibs/lib/python3.11/site-packages/streamlit/runtime/scriptrunner/script_runner.py", line 579, in code_to_exec
    exec(code, module.__dict__)
File "/home/runner/workspace/pages/income_expenses.py", line 191, in <module>
    income_expenses_page()
File "/home/runner/workspace/pages/income_expenses.py", line 156, in income_expenses_page
    df['Payment Source'] = df.apply(
                           ^^^^^^^^^
File "/home/runner/workspace/.pythonlibs/lib/python3.11/site-packages/pandas/core/frame.py", line 10374, in apply
    return op.apply().__finalize__(self, method="apply")
           ^^^^^^^^^^
File "/home/runner/workspace/.pythonlibs/lib/python3.11/site-packages/pandas/core/apply.py", line 916, in apply
    return self.apply_standard()
           ^^^^^^^^^^^^^^^^^^^^^
File "/home/runner/workspace/.pythonlibs/lib/python3.11/site-packages/pandas/core/apply.py", line 1063, in apply_standard
    results, res_index = self.apply_series_generator()
                         ^^^^^^^^^^^^^^^^^^^^^^^^^^^^^
File "/home/runner/workspace/.pythonlibs/lib/python3.11/site-packages/pandas/core/apply.py", line 1081, in apply_series_generator
    results[i] = self.func(v, *self.args, **self.kwargs)
                 ^^^^^^^^^^^^^^^^^^^^^^^^^^^^^^^^^^^^^^^
File "/home/runner/workspace/pages/income_expenses.py", line 158, in <lambda>
    if pd.notna(x['source_name']) else "N/A",
                ~^^^^^^^^^^^^^^^
File "/home/runner/workspace/.pythonlibs/lib/python3.11/site-packages/pandas/core/series.py", line 1121, in __getitem__
    return self._get_value(key)
           ^^^^^^^^^^^^^^^^^^^^
File "/home/runner/workspace/.pythonlibs/lib/python3.11/site-packages/pandas/core/series.py", line 1237, in _get_value
    loc = self.index.get_loc(label)
          ^^^^^^^^^^^^^^^^^^^^^^^^^
File "/home/runner/workspace/.pythonlibs/lib/python3.11/site-packages/pandas/core/indexes/range.py", line 417, in get_loc
    raise KeyError(key)